<?xml version="1.0" ?>
<!-- =================================================================================== -->
<!-- |    This document was autogenerated by xacro from /home/twtoner/catkin_ws3/src/kmriiwa_ros_stack/kmriiwa_description/urdf/robot/kmriiwa.urdf.xacro | -->
<!-- |    EDITING THIS FILE BY HAND IS NOT RECOMMENDED                                 | -->
<!-- =================================================================================== -->
<robot name="kmriiwa">
    <material name="Black">
        <color rgba="0.0 0.0 0.0 1.0" />
    </material>
    <material name="Blue">
        <color rgba="0.0 0.0 0.8 1.0" />
    </material>
    <material name="Green">
        <color rgba="0.0 0.8 0.0 1.0" />
    </material>
    <material name="Grey">
        <color rgba="0.4 0.4 0.4 1.0" />
    </material>
    <material name="DarkGrey">
        <color rgba="0.3 0.3 0.3 1.0" />
    </material>
    <material name="Orange">
        <color rgba="1.0 0.4235294117647059 0.0392156862745098 1.0" />
    </material>
    <material name="Brown">
        <color rgba="0.8705882352941177 0.8117647058823529 0.7647058823529411 1.0" />
    </material>
    <material name="Red">
        <color rgba="0.8 0.0 0.0 1.0" />
    </material>
    <material name="White">
        <color rgba="1.0 1.0 1.0 1.0" />
    </material>
    <material name="aluminum">
        <color rgba="0.5 0.5 0.5 1" />
    </material>
    <!-- TODO 2/13 - double check joint limits against Hojun's repo (these are from iiwa14)-->
    <!-- distance from wheel-floor contact point to base bottom side-->
    <gazebo reference="SF-ISO50-CRG200_Customer">
        <material>Gazebo/Silver</material>
        <kp>1e+13</kp>
        <kd>1.0</kd>
        <mu1>0.2</mu1>
        <mu2>0.2</mu2>
        <selfCollide>true</selfCollide>
        <gravity>true</gravity>
        <plugin name="gazebo_ros_control">
            <robotNamespace>/</robotNamespace>
        </plugin>
    </gazebo>
    <gazebo reference="CRG200_body_1">
        <material>Gazebo/Silver</material>
        <kp>1e+13</kp>
        <kd>1.0</kd>
        <mu1>0.2</mu1>
        <mu2>0.2</mu2>
        <selfCollide>true</selfCollide>
    </gazebo>
    <gazebo reference="CRG200_base_jaw_1">
        <material>Gazebo/Silver</material>
        <kp>1e+13</kp>
        <kd>1.0</kd>
        <mu1>0.2</mu1>
        <mu2>0.2</mu2>
        <minDepth>0.001</minDepth>
        <maxVel>0.0</maxVel>
        <selfCollide>true</selfCollide>
    </gazebo>
    <gazebo reference="CRG200_base_jaw_2">
        <material>Gazebo/Silver</material>
        <kp>1e+13</kp>
        <kd>1.0</kd>
        <mu1>0.2</mu1>
        <mu2>0.2</mu2>
        <minDepth>0.001</minDepth>
        <maxVel>0.0</maxVel>
        <selfCollide>true</selfCollide>
    </gazebo>
    <gazebo reference="CRG200_top_cover_1">
        <material>Gazebo/Silver</material>
        <kp>1e+13</kp>
        <kd>1.0</kd>
        <mu1>0.2</mu1>
        <mu2>0.2</mu2>
        <selfCollide>true</selfCollide>
    </gazebo>
    <gazebo reference="ISO_4762_-_M4_x_12ISO_1">
        <material>Gazebo/Silver</material>
        <kp>1e+13</kp>
        <kd>1.0</kd>
        <mu1>0.2</mu1>
        <mu2>0.2</mu2>
        <selfCollide>true</selfCollide>
    </gazebo>
    <gazebo reference="ISO_4762_-_M4_x_12ISO_2">
        <material>Gazebo/Silver</material>
        <kp>1e+13</kp>
        <kd>1.0</kd>
        <mu1>0.2</mu1>
        <mu2>0.2</mu2>
        <selfCollide>true</selfCollide>
    </gazebo>
    <gazebo reference="ISO_4762_-_M4_x_12ISO_3">
        <material>Gazebo/Silver</material>
        <kp>1e+13</kp>
        <kd>1.0</kd>
        <mu1>0.2</mu1>
        <mu2>0.2</mu2>
        <selfCollide>true</selfCollide>
    </gazebo>
    <gazebo reference="ISO_4762_-_M4_x_12ISO_4">
        <material>Gazebo/Silver</material>
        <kp>1e+13</kp>
        <kd>1.0</kd>
        <mu1>0.2</mu1>
        <mu2>0.2</mu2>
        <selfCollide>true</selfCollide>
    </gazebo>
    <gazebo reference="BE_20-030_CUSTOMER_v1_1">
        <material>Gazebo/Silver</material>
        <kp>1e+13</kp>
        <kd>1.0</kd>
        <mu1>0.2</mu1>
        <mu2>0.2</mu2>
        <selfCollide>true</selfCollide>
    </gazebo>
    <gazebo reference="BE_20-030_CUSTOMER_v1_2">
        <material>Gazebo/Silver</material>
        <kp>1e+13</kp>
        <kd>1.0</kd>
        <mu1>0.2</mu1>
        <mu2>0.2</mu2>
        <selfCollide>true</selfCollide>
    </gazebo>
    <gazebo reference="AC_20-025_CUSTOMER_v1_1">
        <material>Gazebo/Silver</material>
        <kp>1e+13</kp>
        <kd>1.0</kd>
        <mu1>0.2</mu1>
        <mu2>0.2</mu2>
        <selfCollide>true</selfCollide>
    </gazebo>
    <gazebo reference="AC_20-025_CUSTOMER_v1_2">
        <material>Gazebo/Silver</material>
        <kp>1e+13</kp>
        <kd>1.0</kd>
        <mu1>0.2</mu1>
        <mu2>0.2</mu2>
        <selfCollide>true</selfCollide>
    </gazebo>
    <gazebo reference="FT_20-CR_CUSTOMER_v1_1">
        <material>Gazebo/Silver</material>
        <collision name="FT_20-CR_CUSTOMER_v1_1_collision">
            <surface>
                <friction>
                    <torsional>
                        <coefficient>10.0</coefficient>
                        <patch_radius>0.05</patch_radius>
                    </torsional>
                </friction>
                <contact>
                    <poissons_ratio>0.5</poissons_ratio>
                    <elastic_modulus>1e8</elastic_modulus>
                </contact>
            </surface>
        </collision>
        <kp>1e+13</kp>
        <kd>1.0</kd>
        <mu1>200.0</mu1>
        <mu2>200.0</mu2>
        <minDepth>0.001</minDepth>
        <maxVel>0.0</maxVel>
        <selfCollide>true</selfCollide>
    </gazebo>
    <gazebo reference="FT_20-CR_CUSTOMER_v1_2">
        <material>Gazebo/Silver</material>
        <collision name="FT_20-CR_CUSTOMER_v1_2_collision">
            <surface>
                <friction>
                    <torsional>
                        <coefficient>10.0</coefficient>
                        <patch_radius>0.05</patch_radius>
                    </torsional>
                </friction>
                <contact>
                    <poissons_ratio>0.5</poissons_ratio>
                    <elastic_modulus>1e8</elastic_modulus>
                </contact>
            </surface>
        </collision>
        <kp>1e+13</kp>
        <kd>1.0</kd>
        <mu1>200.0</mu1>
        <mu2>200.0</mu2>
        <minDepth>0.001</minDepth>
        <maxVel>0.0</maxVel>
        <selfCollide>true</selfCollide>
    </gazebo>
    <transmission name="Slider01_tran">
        <type>transmission_interface/SimpleTransmission</type>
        <joint name="Slider01">
            <hardwareInterface>hardware_interface/EffortJointInterface</hardwareInterface>
        </joint>
        <actuator name="Slider01_actr">
            <hardwareInterface>hardware_interface/EffortJointInterface</hardwareInterface>
            <mechanicalReduction>1</mechanicalReduction>
        </actuator>
    </transmission>
    <transmission name="Slider02_tran">
        <type>transmission_interface/SimpleTransmission</type>
        <joint name="Slider02">
            <hardwareInterface>hardware_interface/EffortJointInterface</hardwareInterface>
        </joint>
        <actuator name="Slider02_actr">
            <hardwareInterface>hardware_interface/EffortJointInterface</hardwareInterface>
            <mechanicalReduction>1</mechanicalReduction>
        </actuator>
    </transmission>
    <link name="kmriiwa_base_footprint" />
    <joint name="kmriiwa_footprint_to_base_link" type="fixed">
        <parent link="kmriiwa_base_footprint" />
        <child link="kmriiwa_base_link" />
        <origin rpy="0 0 0.0" xyz="0 0 0.025" />
    </joint>
    <link name="kmriiwa_base_link">
        <origin rpy="0 0 0" xyz="0 0 0" />
        <visual>
            <geometry>
                <mesh filename="package://kmriiwa_description/meshes/kmp200/KMP200.dae" />
            </geometry>
            <material name="White" />
        </visual>
        <collision>
            <geometry>
                <mesh filename="package://kmriiwa_description/meshes/kmp200/KMP200.dae" />
            </geometry>
        </collision>
        <inertial>
            <origin rpy="0 0 0" xyz="0 0 0.23500000000000001" />
            <mass value="390" />
            <!-- obtained from KMP200 model on fusion 360 with some modification to align center of mass with the given one-->
            <inertia ixx="28.95" ixy="0.0" ixz="0.0" iyy="44.03" iyz="0.0" izz="33.83" />
        </inertial>
    </link>
    <joint name="kmriiwa_base_link_to_top" type="fixed">
        <parent link="kmriiwa_base_link" />
        <child link="kmriiwa_base_top_link" />
        <origin rpy="0 0 0.0" xyz="0 0 0.6749999999999999" />
    </joint>
    <link name="kmriiwa_base_top_link" />
    <joint name="kmriiwa_laser_B1_joint" type="fixed">
        <parent link="kmriiwa_base_link" />
        <child link="kmriiwa_laser_B1_link" />
        <origin rpy="0 0 -0.7854" xyz="0.464 -0.256 0.1168" />
    </joint>
    <link name="kmriiwa_laser_B1_link">
        <visual>
            <origin rpy="3.1413 0 0" xyz="0 0 0" />
            <geometry>
                <mesh filename="package://kmriiwa_description/meshes/kmp200/sensors/visual/sick_lms1xx.dae" />
            </geometry>
            <material name="DarkGrey" />
        </visual>
        <collision>
            <origin rpy="0 0 0" xyz="0.0 0 0.0" />
            <geometry>
                <mesh filename="package://kmriiwa_description/meshes/kmp200/sensors/collision/sick_lms1xx.stl" />
            </geometry>
        </collision>
        <inertial>
            <mass value="1.2" />
            <inertia ixx="0.002355" ixy="0.0" ixz="0.0" iyy="0.002355" iyz="0.0" izz="0.0002809" />
            <origin xyz="0 0 0" rpy="0 0 0" />
        </inertial>
    </link>
    <joint name="kmriiwa_laser_B4_joint" type="fixed">
        <parent link="kmriiwa_base_link" />
        <child link="kmriiwa_laser_B4_link" />
        <origin rpy="0 0 2.3562" xyz="-0.464 0.256 0.1168" />
    </joint>
    <link name="kmriiwa_laser_B4_link">
        <visual>
            <origin rpy="0 3.1413 3.1413" xyz="0.0 0 0" />
            <geometry>
                <mesh filename="package://kmriiwa_description/meshes/kmp200/sensors/visual/sick_lms1xx.dae" />
            </geometry>
            <material name="DarkGrey" />
        </visual>
        <collision>
            <origin rpy="0 0 0" xyz="0 0 0" />
            <geometry>
                <mesh filename="package://kmriiwa_description/meshes/kmp200/sensors/collision/sick_lms1xx.stl" />
            </geometry>
        </collision>
        <inertial>
            <mass value="1.2" />
            <inertia ixx="0.002355" ixy="0.0" ixz="0.0" iyy="0.002355" iyz="0.0" izz="0.0002809" />
            <origin xyz="0 0 0" rpy="0 0 0" />
        </inertial>
    </link>
    <link name="kmriiwa_front_left_wheel_link">
        <visual>
            <origin rpy="0 0 0" xyz="0 0 0" />
            <geometry>
                <mesh filename="package://kmriiwa_description/meshes/kmp200/wheels/omni_wheel_1.dae" scale="1.06695 1.06695 1.06695" />
            </geometry>
        </visual>
        <collision>
            <origin rpy="1.57 0 0" xyz="0 0 0" />
            <geometry>
                <cylinder length="0.132" radius="0.125" />
            </geometry>
        </collision>
        <inertial>
            <mass value="0.1" />
            <origin xyz="0 0 0" rpy="0 0 0" />
            <inertia ixx="0.03" iyy="0.03" izz="0.03" ixy="0.0" ixz="0.0" iyz="0.0" />
        </inertial>
    </link>
    <link name="kmriiwa_front_right_wheel_link">
        <visual>
            <origin rpy="0 0 0" xyz="0 0 0" />
            <geometry>
                <mesh filename="package://kmriiwa_description/meshes/kmp200/wheels/omni_wheel_1.dae" scale="1.06695 1.06695 1.06695" />
            </geometry>
        </visual>
        <collision>
            <origin rpy="1.57 0 0" xyz="0 0 0" />
            <geometry>
                <cylinder length="0.132" radius="0.125" />
            </geometry>
        </collision>
        <inertial>
            <mass value="0.1" />
            <origin xyz="0 0 0" rpy="0 0 0" />
            <inertia ixx="0.03" iyy="0.03" izz="0.03" ixy="0.0" ixz="0.0" iyz="0.0" />
        </inertial>
    </link>
    <link name="kmriiwa_back_left_wheel_link">
        <visual>
            <origin rpy="0 0 0" xyz="0 0 0" />
            <geometry>
                <mesh filename="package://kmriiwa_description/meshes/kmp200/wheels/omni_wheel_1.dae" scale="1.06695 1.06695 1.06695" />
            </geometry>
        </visual>
        <collision>
            <origin rpy="1.57 0 0" xyz="0 0 0" />
            <geometry>
                <cylinder length="0.132" radius="0.125" />
            </geometry>
        </collision>
        <inertial>
            <mass value="0.1" />
            <origin xyz="0 0 0" rpy="0 0 0" />
            <inertia ixx="0.03" iyy="0.03" izz="0.03" ixy="0.0" ixz="0.0" iyz="0.0" />
        </inertial>
    </link>
    <link name="kmriiwa_back_right_wheel_link">
        <visual>
            <origin rpy="0 0 0" xyz="0 0 0" />
            <geometry>
                <mesh filename="package://kmriiwa_description/meshes/kmp200/wheels/omni_wheel_1.dae" scale="1.06695 1.06695 1.06695" />
            </geometry>
        </visual>
        <collision>
            <origin rpy="1.57 0 0" xyz="0 0 0" />
            <geometry>
                <cylinder length="0.132" radius="0.125" />
            </geometry>
        </collision>
        <!-- <inertial>
            <mass value="14"/>
            <inertia ixx="0.075016" ixy="0.0" ixz="0.0" iyy="0.075016" iyz="0.0" izz="0.109375"/>
        </inertial> -->
        <inertial>
            <mass value="0.1" />
            <origin xyz="0 0 0" rpy="0 0 0" />
            <inertia ixx="0.03" iyy="0.03" izz="0.03" ixy="0.0" ixz="0.0" iyz="0.0" />
        </inertial>
    </link>
    <joint name="kmriiwa_front_left_wheel_joint" type="fixed">
        <parent link="kmriiwa_base_link" />
        <child link="kmriiwa_front_left_wheel_link" />
        <axis xyz="0 1 0" />
        <origin xyz="0.28 0.1825 0.1" />
        <limit effort="100" velocity="100" />
        <joint_properties damping="0.0" friction="0.0" />
    </joint>
    <joint name="kmriiwa_front_right_wheel_joint" type="fixed">
        <parent link="kmriiwa_base_link" />
        <child link="kmriiwa_front_right_wheel_link" />
        <origin xyz="0.28 -0.1825 0.1" />
        <axis xyz="0 1 0" />
        <limit effort="100" velocity="100" />
        <joint_properties damping="0.0" friction="0.0" />
    </joint>
    <joint name="kmriiwa_back_left_wheel_joint" type="fixed">
        <parent link="kmriiwa_base_link" />
        <child link="kmriiwa_back_left_wheel_link" />
        <origin xyz="-0.28 0.1825 0.1" />
        <axis xyz="0 1 0" />
        <limit effort="100" velocity="100" />
        <joint_properties damping="0.0" friction="0.0" />
    </joint>
    <joint name="kmriiwa_back_right_wheel_joint" type="fixed">
        <parent link="kmriiwa_base_link" />
        <child link="kmriiwa_back_right_wheel_link" />
        <origin xyz="-0.28 -0.1825 0.1" />
        <axis xyz="0 1 0" />
        <limit effort="100" velocity="100" />
        <joint_properties damping="0.0" friction="0.0" />
    </joint>
    <!-- Gazebo planar move plugin -->
    <!-- <gazebo>
        <plugin name='planar_move' filename='libgazebo_ros_planar_move.so'>
            <robotNamespace>/${robot_name}</robotNamespace>
            <commandTopic>base/command/cmd_vel</commandTopic>
            <odometryTopic>base/state/odom</odometryTopic>
            <update_rate>100</update_rate>
            <publish_rate>10</publish_rate>

            
            <publish_odom>true</publish_odom>
            <publish_odom_tf>true</publish_odom_tf>

            <odometryFrame>odom</odometryFrame>
            <robotBaseFrame>base_link</robotBaseFrame>
            <odometryRate>20.0</odometryRate>

            <covariance_x>0.0001</covariance_x>
            <covariance_y>0.0001</covariance_y>
            <covariance_yaw>0.01</covariance_yaw>
        </plugin>
    </gazebo>  -->
    <!-- Hector ros force based planar move plugin -->
    <gazebo>
        <plugin filename="libgazebo_ros_force_based_move.so" name="ros_force_based_move">
            <robotNamespace>/kmriiwa</robotNamespace>
            <commandTopic>base/command/cmd_vel</commandTopic>
            <odometryTopic>base/state/odom</odometryTopic>
            <robotBaseFrame>kmriiwa_base_footprint</robotBaseFrame>
            <publishOdometryTf>true</publishOdometryTf>
            <odometryFrame>kmriiwa_odom</odometryFrame>
            <odometryRate>20.0</odometryRate>
            <yaw_velocity_p_gain>500</yaw_velocity_p_gain>
            <x_velocity_p_gain>1000</x_velocity_p_gain>
            <y_velocity_p_gain>1000</y_velocity_p_gain>
        </plugin>
    </gazebo>
    <gazebo reference="kmriiwa_laser_B1_link">
        <sensor name="sensor_B1" type="ray">
            <always_on>true</always_on>
            <visualize>true</visualize>
            <update_rate>10</update_rate>
            <ray>
                <scan>
                    <horizontal>
                        <samples>640</samples>
                        <resolution>1.000000</resolution>
                        <min_angle>-2.30383</min_angle>
                        <max_angle>2.30383</max_angle>
                    </horizontal>
                </scan>
                <range>
                    <min>0.12</min>
                    <max>15</max>
                    <resolution>0.0100</resolution>
                </range>
                <noise>
                    <type>gaussian</type>
                    <mean>0.0</mean>
                    <stddev>0.01</stddev>
                </noise>
            </ray>
            <plugin filename="libgazebo_ros_laser.so" name="gazebo_sensor_B1_controller">
                <robotNamespace>/</robotNamespace>
                <topicName>/kmriiwa/base/state/LaserB1Scan</topicName>
                <output_type>sensor_msgs/LaserScan</output_type>
                <frameName>kmriiwa_laser_B1_link</frameName>
            </plugin>
        </sensor>
    </gazebo>
    <gazebo reference="kmriiwa_laser_B4_link">
        <sensor name="sensor_B4" type="ray">
            <always_on>true</always_on>
            <visualize>true</visualize>
            <update_rate>10</update_rate>
            <ray>
                <scan>
                    <horizontal>
                        <samples>640</samples>
                        <resolution>1.000000</resolution>
                        <min_angle>-2.30383</min_angle>
                        <max_angle>2.30383</max_angle>
                    </horizontal>
                </scan>
                <range>
                    <min>0.12</min>
                    <max>15</max>
                    <resolution>0.0100</resolution>
                </range>
                <noise>
                    <type>gaussian</type>
                    <mean>0.0</mean>
                    <stddev>0.01</stddev>
                </noise>
            </ray>
            <plugin filename="libgazebo_ros_laser.so" name="gazebo_sensor_B4_controller">
                <robotNamespace>/</robotNamespace>
                <topicName>/kmriiwa/base/state/LaserB4Scan</topicName>
                <output_type>sensor_msgs/LaserScan</output_type>
                <frameName>kmriiwa_laser_B4_link</frameName>
            </plugin>
        </sensor>
    </gazebo>
    <gazebo reference="kmriiwa_base_link">
        <material>Gazebo/Grey</material>
    </gazebo>
    <gazebo reference="kmriiwa_front_left_wheel_link">
        <mu1 value="0.0" />
        <mu2 value="0.0" />
        <surface>
            <contact>
                <collide_without_contact>true</collide_without_contact>
            </contact>
        </surface>
    </gazebo>
    <gazebo reference="kmriiwa_front_right_wheel_link">
        <mu1 value="0.0" />
        <mu2 value="0.0" />
        <surface>
            <contact>
                <collide_without_contact>true</collide_without_contact>
            </contact>
        </surface>
    </gazebo>
    <gazebo reference="kmriiwa_back_left_wheel_link">
        <mu1 value="0.0" />
        <mu2 value="0.0" />
        <surface>
            <contact>
                <collide_without_contact>true</collide_without_contact>
            </contact>
        </surface>
    </gazebo>
    <gazebo reference="kmriiwa_back_right_wheel_link">
        <mu1 value="0.0" />
        <mu2 value="0.0" />
        <surface>
            <contact>
                <collide_without_contact>true</collide_without_contact>
            </contact>
        </surface>
    </gazebo>
    <!--riser flange-->
    <joint name="kmriiwa_base_top_riser_flange_joint" type="fixed">
        <parent link="kmriiwa_base_top_link" />
        <child link="kmriiwa_riser_flange_link" />
        <origin rpy="0 0 -1.5708" xyz="0.363 -0.184 -0.01" />
    </joint>
    <link name="kmriiwa_riser_flange_link">
        <visual>
            <origin rpy="0 0 0" xyz="0 0 0" />
            <geometry>
                <cylinder length="0.0" radius="0.121" />
            </geometry>
            <material name="White" />
        </visual>
        <collision>
            <origin rpy="0 0 0" xyz="0 0 0" />
            <geometry>
                <cylinder length="0.0" radius="0.121" />
            </geometry>
        </collision>
        <inertial>
            <mass value="0.1" />
            <origin xyz="0 0 0" rpy="0 0 0" />
            <inertia ixx="0.03" iyy="0.03" izz="0.03" ixy="0.0" ixz="0.0" iyz="0.0" />
        </inertial>
    </link>
    <!--joint between {parent} and link_0-->
    <joint name="kmriiwa_riser_flange_link_kmriiwa_joint" type="fixed">
        <origin rpy="0 0 0" xyz="0 0 0.0" />
        <parent link="kmriiwa_riser_flange_link" />
        <child link="kmriiwa_link_0" />
    </joint>
    <link name="kmriiwa_link_0">
        <inertial>
            <origin rpy="0 0 0" xyz="-0.012832431040764161 -4.5637556731516346e-08 0.07010426148644754" />
            <mass value="5" />
            <inertia ixx="0.05" ixy="0" ixz="0" iyy="0.06" iyz="0" izz="0.03" />
        </inertial>
        <visual>
            <origin rpy="0 0 0" xyz="0 0 0" />
            <geometry>
                <mesh filename="package://kmriiwa_description/meshes/iiwa7/visual/link_0.stl" scale="0.001 0.001 0.001" />
            </geometry>
            <material name="Grey" />
        </visual>
        <collision>
            <origin rpy="0 0 0" xyz="0 0 0" />
            <geometry>
                <mesh filename="package://kmriiwa_description/meshes/iiwa7/collision/link_0.stl" scale="0.001 0.001 0.001" />
            </geometry>
            <material name="Grey" />
        </collision>
        <self_collision_checking>
            <origin rpy="0 0 0" xyz="0 0 0" />
            <geometry>
                <capsule length="0.25" radius="0.15" />
            </geometry>
        </self_collision_checking>
    </link>
    <!-- joint between link_0 and link_1 -->
    <joint name="kmriiwa_joint_1" type="revolute">
        <parent link="kmriiwa_link_0" />
        <child link="kmriiwa_link_1" />
        <origin rpy="0 0 0" xyz="0.0 0.0 0.1475" />
        <axis xyz="0 0 1" />
        <limit effort="100" lower="-2.9670597283903604" upper="2.9670597283903604" velocity="10" />
        <safety_controller k_position="100" k_velocity="2" soft_lower_limit="-2.9321531433504737" soft_upper_limit="2.9321531433504737" />
        <dynamics damping="0.5" />
    </joint>
    <link name="kmriiwa_link_1">
        <inertial>
            <origin rpy="0 0 0" xyz="9.615003024343416e-08 -0.03473351023743466 0.12351616001638635" />
            <mass value="3.4525" />
            <inertia ixx="0.02183" ixy="0" ixz="0" iyy="0.007703" iyz="-0.003887" izz="0.02083" />
        </inertial>
        <visual>
            <origin rpy="0 0 0" xyz="-0.0 0.0 -0.1475" />
            <geometry>
                <mesh filename="package://kmriiwa_description/meshes/iiwa7/visual/link_1.stl" scale="0.001 0.001 0.001" />
            </geometry>
            <material name="Orange" />
        </visual>
        <collision>
            <origin rpy="0 0 0" xyz="-0.0 0.0 -0.1475" />
            <geometry>
                <mesh filename="package://kmriiwa_description/meshes/iiwa7/collision/link_1.stl" scale="0.001 0.001 0.001" />
            </geometry>
            <material name="Orange" />
        </collision>
    </link>
    <!-- joint between link_1 and link_2 -->
    <joint name="kmriiwa_joint_2" type="revolute">
        <parent link="kmriiwa_link_1" />
        <child link="kmriiwa_link_2" />
        <origin rpy="0 0 0" xyz="-0.0 -0.0105 0.193" />
        <axis xyz="0 1 0" />
        <limit effort="100" lower="-2.0943951023931953" upper="2.0943951023931953" velocity="10" />
        <safety_controller k_position="100" k_velocity="2" soft_lower_limit="-2.0594885173533086" soft_upper_limit="2.0594885173533086" />
        <dynamics damping="0.5" />
    </joint>
    <link name="kmriiwa_link_2">
        <inertial>
            <origin rpy="0 0 0" xyz="5.3961961621630917e-08 0.04491512185097363 0.06732557420480756" />
            <mass value="3.4821" />
            <inertia ixx="0.02076" ixy="0" ixz="-0.003626" iyy="0.02179" iyz="0" izz="0.00779" />
        </inertial>
        <visual>
            <origin rpy="0 0 0" xyz="0.0 0.0105 -0.3405" />
            <geometry>
                <mesh filename="package://kmriiwa_description/meshes/iiwa7/visual/link_2.stl" scale="0.001 0.001 0.001" />
            </geometry>
            <material name="Orange" />
        </visual>
        <collision>
            <origin rpy="0 0 0" xyz="0.0 0.0105 -0.3405" />
            <geometry>
                <mesh filename="package://kmriiwa_description/meshes/iiwa7/collision/link_2.stl" scale="0.001 0.001 0.001" />
            </geometry>
            <material name="Orange" />
        </collision>
    </link>
    <!-- joint between link_2 and link_3 -->
    <joint name="kmriiwa_joint_3" type="revolute">
        <parent link="kmriiwa_link_2" />
        <child link="kmriiwa_link_3" />
        <origin rpy="0 0 0" xyz="0.0 0.0105 0.1745" />
        <axis xyz="0 0 1" />
        <limit effort="100" lower="-2.9670597283903604" upper="2.9670597283903604" velocity="10" />
        <safety_controller k_position="100" k_velocity="2" soft_lower_limit="-2.9321531433504737" soft_upper_limit="2.9321531433504737" />
        <dynamics damping="0.5" />
    </joint>
    <link name="kmriiwa_link_3">
        <inertial>
            <origin rpy="0 0 0" xyz="1.207224751269193e-08 0.029563686162089268 0.13650353945673122" />
            <mass value="4.05623" />
            <inertia ixx="0.03204" ixy="0" ixz="0" iyy="0.00972" iyz="0.006227" izz="0.03042" />
        </inertial>
        <visual>
            <origin rpy="0 0 0" xyz="0.0 0.0 -0.515" />
            <geometry>
                <mesh filename="package://kmriiwa_description/meshes/iiwa7/visual/link_3.stl" scale="0.001 0.001 0.001" />
            </geometry>
            <material name="Orange" />
        </visual>
        <collision>
            <origin rpy="0 0 0" xyz="0.0 0.0 -0.515" />
            <geometry>
                <mesh filename="package://kmriiwa_description/meshes/iiwa7/collision/link_3.stl" scale="0.001 0.001 0.001" />
            </geometry>
            <material name="Orange" />
        </collision>
    </link>
    <!-- joint between link_3 and link_4 -->
    <joint name="kmriiwa_joint_4" type="revolute">
        <parent link="kmriiwa_link_3" />
        <child link="kmriiwa_link_4" />
        <origin rpy="0 0 0" xyz="0.0 0.0105 0.2255" />
        <axis xyz="0 -1 0" />
        <limit effort="100" lower="-2.0943951023931953" upper="2.0943951023931953" velocity="10" />
        <safety_controller k_position="100" k_velocity="2" soft_lower_limit="-2.0594885173533086" soft_upper_limit="2.0594885173533086" />
        <dynamics damping="0.5" />
    </joint>
    <link name="kmriiwa_link_4">
        <inertial>
            <origin rpy="0 0 0" xyz="-5.485084286249875e-08 -0.044915740111597394 0.06732540221831629" />
            <mass value="3.4822" />
            <inertia ixx="0.02178" ixy="0" ixz="0" iyy="0.02075" iyz="-0.003625" izz="0.007785" />
        </inertial>
        <visual>
            <origin rpy="0 0 0" xyz="0.0 -0.0105 -0.7405" />
            <geometry>
                <mesh filename="package://kmriiwa_description/meshes/iiwa7/visual/link_4.stl" scale="0.001 0.001 0.001" />
            </geometry>
            <material name="Orange" />
        </visual>
        <collision>
            <origin rpy="0 0 0" xyz="0.0 -0.0105 -0.7405" />
            <geometry>
                <mesh filename="package://kmriiwa_description/meshes/iiwa7/collision/link_4.stl" scale="0.001 0.001 0.001" />
            </geometry>
            <material name="Orange" />
        </collision>
    </link>
    <!-- joint between link_4 and link_5 -->
    <joint name="kmriiwa_joint_5" type="revolute">
        <parent link="kmriiwa_link_4" />
        <child link="kmriiwa_link_5" />
        <origin rpy="0 0 0" xyz="0.0 -0.0105 0.1745" />
        <axis xyz="0 0 1" />
        <limit effort="100" lower="-2.9670597283903604" upper="2.9670597283903604" velocity="10" />
        <safety_controller k_position="100" k_velocity="2" soft_lower_limit="-2.9321531433504737" soft_upper_limit="2.9321531433504737" />
        <dynamics damping="0.5" />
    </joint>
    <link name="kmriiwa_link_5">
        <inertial>
            <origin rpy="0 0 0" xyz="-8.834784191987874e-09 -0.02138659031332106 0.08546853677464128" />
            <mass value="2.1633" />
            <inertia ixx="0.01287" ixy="0" ixz="0" iyy="0.005708" iyz="-0.003946" izz="0.01112" />
        </inertial>
        <visual>
            <origin rpy="0 0 0" xyz="0.0 0.0 -0.915" />
            <geometry>
                <mesh filename="package://kmriiwa_description/meshes/iiwa7/visual/link_5.stl" scale="0.001 0.001 0.001" />
            </geometry>
            <material name="Orange" />
        </visual>
        <collision>
            <origin rpy="0 0 0" xyz="0.0 0.0 -0.915" />
            <geometry>
                <mesh filename="package://kmriiwa_description/meshes/iiwa7/collision/link_5.stl" scale="0.001 0.001 0.001" />
            </geometry>
            <material name="Orange" />
        </collision>
    </link>
    <!-- joint between link_5 and link_6 -->
    <joint name="kmriiwa_joint_6" type="revolute">
        <parent link="kmriiwa_link_5" />
        <child link="kmriiwa_link_6" />
        <origin rpy="0 0 0" xyz="0.0 -0.0707 0.2255" />
        <axis xyz="0 1 0" />
        <limit effort="100" lower="-2.0943951023931953" upper="2.0943951023931953" velocity="10" />
        <safety_controller k_position="100" k_velocity="2" soft_lower_limit="-2.0594885173533086" soft_upper_limit="2.0594885173533086" />
        <dynamics damping="0.5" />
    </joint>
    <link name="kmriiwa_link_6">
        <inertial>
            <origin rpy="0 0 0" xyz="-2.784005425940048e-07 0.07098688488077398 0.002115616520607766" />
            <mass value="2.3466" />
            <inertia ixx="0.006509" ixy="0" ixz="0" iyy="0.006259" iyz="0.00031891" izz="0.004527" />
        </inertial>
        <visual>
            <origin rpy="0 0 0" xyz="0.0 0.0707 -1.1405" />
            <geometry>
                <mesh filename="package://kmriiwa_description/meshes/iiwa7/visual/link_6.stl" scale="0.001 0.001 0.001" />
            </geometry>
            <material name="Orange" />
        </visual>
        <collision>
            <origin rpy="0 0 0" xyz="0.0 0.0707 -1.1405" />
            <geometry>
                <mesh filename="package://kmriiwa_description/meshes/iiwa7/collision/link_6.stl" scale="0.001 0.001 0.001" />
            </geometry>
            <material name="Orange" />
        </collision>
    </link>
    <!-- joint between link_6 and link_7 -->
    <joint name="kmriiwa_joint_7" type="revolute">
        <parent link="kmriiwa_link_6" />
        <child link="kmriiwa_link_7" />
        <origin rpy="0 0 0" xyz="0.0 0.0705 0.0909" />
        <axis xyz="0 0 1" />
        <limit effort="100" lower="-3.0543261909900763" upper="3.0543261909900763" velocity="10" />
        <safety_controller k_position="100" k_velocity="2" soft_lower_limit="-3.01941960595019" soft_upper_limit="3.01941960595019" />
        <dynamics damping="0.5" />
    </joint>
    <link name="kmriiwa_link_7">
        <inertial>
            <origin rpy="0 0 0" xyz="4.659054144329294e-06 1.7291653306211654e-08 0.009981852938580671" />
            <mass value="3.129" />
            <inertia ixx="0.01464" ixy="0.0005912" ixz="0" iyy="0.01465" iyz="0" izz="0.002872" />
        </inertial>
        <visual>
            <origin rpy="0 0 0" xyz="0.0 0.0002 -1.2314" />
            <geometry>
                <mesh filename="package://kmriiwa_description/meshes/iiwa7/visual/link_7.stl" scale="0.001 0.001 0.001" />
            </geometry>
            <material name="Grey" />
        </visual>
        <collision>
            <origin rpy="0 0 0" xyz="0.0 0.0002 -1.2314" />
            <geometry>
                <mesh filename="package://kmriiwa_description/meshes/iiwa7/collision/link_7.stl" scale="0.001 0.001 0.001" />
            </geometry>
            <material name="Grey" />
        </collision>
    </link>
    <joint name="kmriiwa_joint_ee" type="fixed">
        <parent link="kmriiwa_link_7" />
        <child link="kmriiwa_link_ee" />
        <origin rpy="0 0 0" xyz="0 0 0.045" />
    </joint>
    <link name="kmriiwa_link_ee" />
    <!-- Enable the Joint Feedback -->
    <gazebo reference="kmriiwa_joint_7">
        <provideFeedback>true</provideFeedback>
    </gazebo>
    <!-- The ft_sensor plugin -->
    <gazebo>
        <plugin filename="libgazebo_ros_ft_sensor.so" name="ft_sensor">
            <updateRate>50.0</updateRate>
            <topicName>/kmriiwa/state/CartesianWrench</topicName>
            <jointName>kmriiwa_joint_7</jointName>
        </plugin>
    </gazebo>
    <!-- Load Gazebo lib and set the robot namespace -->
    <gazebo>
        <plugin filename="libgazebo_ros_control.so" name="gazebo_ros_control">
            <robotNamespace>/kmriiwa/arm</robotNamespace>
            <robotParam>/kmriiwa/robot_description</robotParam>
        </plugin>
    </gazebo>
    <!-- Link0 -->
    <gazebo reference="kmriiwa_link_0">
        <material>Gazebo/Grey</material>
        <mu1>0.2</mu1>
        <mu2>0.2</mu2>
    </gazebo>
    <!-- Link1 -->
    <gazebo reference="kmriiwa_link_1">
        <material>Gazebo/Orange</material>
        <mu1>0.2</mu1>
        <mu2>0.2</mu2>
    </gazebo>
    <!-- Link2 -->
    <gazebo reference="kmriiwa_link_2">
        <material>Gazebo/Orange</material>
        <mu1>0.2</mu1>
        <mu2>0.2</mu2>
    </gazebo>
    <!-- Link3 -->
    <gazebo reference="kmriiwa_link_3">
        <material>Gazebo/Orange</material>
        <mu1>0.2</mu1>
        <mu2>0.2</mu2>
    </gazebo>
    <!-- Link4 -->
    <gazebo reference="kmriiwa_link_4">
        <material>Gazebo/Orange</material>
        <mu1>0.2</mu1>
        <mu2>0.2</mu2>
    </gazebo>
    <!-- Link5 -->
    <gazebo reference="kmriiwa_link_5">
        <material>Gazebo/Orange</material>
        <mu1>0.2</mu1>
        <mu2>0.2</mu2>
    </gazebo>
    <!-- Link6 -->
    <gazebo reference="kmriiwa_link_6">
        <material>Gazebo/Orange</material>
        <mu1>0.2</mu1>
        <mu2>0.2</mu2>
    </gazebo>
    <!-- Link7 -->
    <gazebo reference="kmriiwa_link_7">
        <material>Gazebo/Grey</material>
        <mu1>0.2</mu1>
        <mu2>0.2</mu2>
    </gazebo>
    <transmission name="kmriiwa_tran_1">
        <robotNamespace>/kmriiwa/arm</robotNamespace>
        <type>transmission_interface/SimpleTransmission</type>
        <joint name="kmriiwa_joint_1">
            <hardwareInterface>hardware_interface/PositionJointInterface</hardwareInterface>
        </joint>
        <actuator name="kmriiwa_motor_1">
            <hardwareInterface>hardware_interface/PositionJointInterface</hardwareInterface>
            <mechanicalReduction>1</mechanicalReduction>
        </actuator>
    </transmission>
    <transmission name="kmriiwa_tran_2">
        <robotNamespace>/kmriiwa/arm</robotNamespace>
        <type>transmission_interface/SimpleTransmission</type>
        <joint name="kmriiwa_joint_2">
            <hardwareInterface>hardware_interface/PositionJointInterface</hardwareInterface>
        </joint>
        <actuator name="kmriiwa_motor_2">
            <hardwareInterface>hardware_interface/PositionJointInterface</hardwareInterface>
            <mechanicalReduction>1</mechanicalReduction>
        </actuator>
    </transmission>
    <transmission name="kmriiwa_tran_3">
        <robotNamespace>/kmriiwa/arm</robotNamespace>
        <type>transmission_interface/SimpleTransmission</type>
        <joint name="kmriiwa_joint_3">
            <hardwareInterface>hardware_interface/PositionJointInterface</hardwareInterface>
        </joint>
        <actuator name="kmriiwa_motor_3">
            <hardwareInterface>hardware_interface/PositionJointInterface</hardwareInterface>
            <mechanicalReduction>1</mechanicalReduction>
        </actuator>
    </transmission>
    <transmission name="kmriiwa_tran_4">
        <robotNamespace>/kmriiwa/arm</robotNamespace>
        <type>transmission_interface/SimpleTransmission</type>
        <joint name="kmriiwa_joint_4">
            <hardwareInterface>hardware_interface/PositionJointInterface</hardwareInterface>
        </joint>
        <actuator name="kmriiwa_motor_4">
            <hardwareInterface>hardware_interface/PositionJointInterface</hardwareInterface>
            <mechanicalReduction>1</mechanicalReduction>
        </actuator>
    </transmission>
    <transmission name="kmriiwa_tran_5">
        <robotNamespace>/kmriiwa/arm</robotNamespace>
        <type>transmission_interface/SimpleTransmission</type>
        <joint name="kmriiwa_joint_5">
            <hardwareInterface>hardware_interface/PositionJointInterface</hardwareInterface>
        </joint>
        <actuator name="kmriiwa_motor_5">
            <hardwareInterface>hardware_interface/PositionJointInterface</hardwareInterface>
            <mechanicalReduction>1</mechanicalReduction>
        </actuator>
    </transmission>
    <transmission name="kmriiwa_tran_6">
        <robotNamespace>/kmriiwa/arm</robotNamespace>
        <type>transmission_interface/SimpleTransmission</type>
        <joint name="kmriiwa_joint_6">
            <hardwareInterface>hardware_interface/PositionJointInterface</hardwareInterface>
        </joint>
        <actuator name="kmriiwa_motor_6">
            <hardwareInterface>hardware_interface/PositionJointInterface</hardwareInterface>
            <mechanicalReduction>1</mechanicalReduction>
        </actuator>
    </transmission>
    <transmission name="kmriiwa_tran_7">
        <robotNamespace>/kmriiwa/arm</robotNamespace>
        <type>transmission_interface/SimpleTransmission</type>
        <joint name="kmriiwa_joint_7">
            <hardwareInterface>hardware_interface/PositionJointInterface</hardwareInterface>
        </joint>
        <actuator name="kmriiwa_motor_7">
            <hardwareInterface>hardware_interface/PositionJointInterface</hardwareInterface>
            <mechanicalReduction>1</mechanicalReduction>
        </actuator>
    </transmission>
    <!-- This file is a placeholder which is included by default from
       kmriiwa.urdf.xacro. If a robot is being customized and requires
       additional URDF, add them here. -->
    <link name="SF-ISO50-CRG200_Customer">
        <inertial>
            <origin rpy="0 0 0" xyz="-0.000839387245317249 1.3268462236734284e-07 0.0056277999249054874" />
            <mass value="0.16831092346442011" />
            <inertia ixx="5.7e-05" ixy="-0.0" ixz="1e-06" iyy="0.000144" iyz="0.0" izz="0.000197" />
        </inertial>
        <visual>
            <origin rpy="0 0 0" xyz="0 0 0" />
            <geometry>
                <mesh filename="package://gripkit_cr_plus_l_bb_description/meshes/SF-ISO50-CRG200_Customer.stl" scale="0.001 0.001 0.001" />
            </geometry>
            <material name="silver" />
        </visual>
        <collision>
            <origin rpy="0 0 0" xyz="0 0 0" />
            <geometry>
                <mesh filename="package://gripkit_cr_plus_l_bb_description/meshes/SF-ISO50-CRG200_Customer.stl" scale="0.001 0.001 0.001" />
            </geometry>
        </collision>
    </link>
    <link name="CRG200_body">
        <inertial>
            <origin rpy="0 0 0" xyz="-0.046013419522296255 0.023500046460400374 0.029719376870480135" />
            <mass value="1.024019455093708" />
            <inertia ixx="0.000598" ixy="0.0" ixz="-0.0" iyy="0.001224" iyz="-0.0" izz="0.001229" />
        </inertial>
        <visual>
            <origin rpy="0 0 0" xyz="-0.046 0.0235 -0.011" />
            <geometry>
                <mesh filename="package://gripkit_cr_plus_l_bb_description/meshes/CRG200_body.stl" scale="0.001 0.001 0.001" />
            </geometry>
            <material name="silver" />
        </visual>
        <collision>
            <origin rpy="0 0 0" xyz="-0.046 0.0235 -0.011" />
            <geometry>
                <mesh filename="package://gripkit_cr_plus_l_bb_description/meshes/CRG200_body.stl" scale="0.001 0.001 0.001" />
            </geometry>
        </collision>
    </link>
    <link name="CRG200_base_jaw_1">
        <inertial>
            <origin rpy="0 0 0" xyz="-0.001116596745818358 -2.0816681711721685e-17 0.004896836508835337" />
            <mass value="0.028974809674202275" />
            <inertia ixx="0.0" ixy="0.0" ixz="0.0" iyy="5e-06" iyz="0.0" izz="5e-06" />
        </inertial>
        <visual>
            <origin rpy="0 0 0" xyz="-0.0 0.0185 -0.0686" />
            <geometry>
                <mesh filename="package://gripkit_cr_plus_l_bb_description/meshes/CRG200_base_jaw_1.stl" scale="0.001 0.001 0.001" />
            </geometry>
            <material name="silver" />
        </visual>
        <collision>
            <origin rpy="0 0 0" xyz="-0.0 0.0185 -0.0686" />
            <geometry>
                <mesh filename="package://gripkit_cr_plus_l_bb_description/meshes/CRG200_base_jaw_1.stl" scale="0.001 0.001 0.001" />
            </geometry>
        </collision>
    </link>
    <link name="CRG200_base_jaw_2">
        <inertial>
            <origin rpy="0 0 0" xyz="0.001116596745818374 1.0408340855860843e-17 0.004896836508835337" />
            <mass value="0.028974809674202275" />
            <inertia ixx="0.0" ixy="0.0" ixz="-0.0" iyy="5e-06" iyz="-0.0" izz="5e-06" />
        </inertial>
        <visual>
            <origin rpy="0 0 0" xyz="-0.0 -0.0185 -0.0686" />
            <geometry>
                <mesh filename="package://gripkit_cr_plus_l_bb_description/meshes/CRG200_base_jaw_2.stl" scale="0.001 0.001 0.001" />
            </geometry>
            <material name="silver" />
        </visual>
        <collision>
            <origin rpy="0 0 0" xyz="-0.0 -0.0185 -0.0686" />
            <geometry>
                <mesh filename="package://gripkit_cr_plus_l_bb_description/meshes/CRG200_base_jaw_2.stl" scale="0.001 0.001 0.001" />
            </geometry>
        </collision>
    </link>
    <link name="CRG200_top_cover">
        <inertial>
            <origin rpy="0 0 0" xyz="-2.837104009083995e-09 7.283818491274739e-09 0.0040439255937821245" />
            <mass value="0.117790703444327" />
            <inertia ixx="3.5e-05" ixy="-0.0" ixz="0.0" iyy="0.000112" iyz="-0.0" izz="0.000144" />
        </inertial>
        <visual>
            <origin rpy="0 0 0" xyz="-0.0 0.0 -0.0711" />
            <geometry>
                <mesh filename="package://gripkit_cr_plus_l_bb_description/meshes/CRG200_top_cover.stl" scale="0.001 0.001 0.001" />
            </geometry>
            <material name="silver" />
        </visual>
        <collision>
            <origin rpy="0 0 0" xyz="-0.0 0.0 -0.0711" />
            <geometry>
                <mesh filename="package://gripkit_cr_plus_l_bb_description/meshes/CRG200_top_cover.stl" scale="0.001 0.001 0.001" />
            </geometry>
        </collision>
    </link>
    <link name="ISO_4762_-_M4_x_12ISO_1">
        <inertial>
            <origin rpy="0 0 0" xyz="-6.938893903907228e-18 4.0060663120122797e-13 0.0022480078452116357" />
            <mass value="0.002203374250243251" />
            <inertia ixx="0.0" ixy="0.0" ixz="0.0" iyy="0.0" iyz="0.0" izz="0.0" />
        </inertial>
        <visual>
            <origin rpy="0 0 0" xyz="0.046 0.0235 -0.0065" />
            <geometry>
                <mesh filename="package://gripkit_cr_plus_l_bb_description/meshes/ISO_4762_-_M4_x_12ISO_1.stl" scale="0.001 0.001 0.001" />
            </geometry>
            <material name="silver" />
        </visual>
        <collision>
            <origin rpy="0 0 0" xyz="0.046 0.0235 -0.0065" />
            <geometry>
                <mesh filename="package://gripkit_cr_plus_l_bb_description/meshes/ISO_4762_-_M4_x_12ISO_1.stl" scale="0.001 0.001 0.001" />
            </geometry>
        </collision>
    </link>
    <link name="ISO_4762_-_M4_x_12ISO_2">
        <inertial>
            <origin rpy="0 0 0" xyz="6.938893903907228e-18 4.0060663120122797e-13 0.0022480078452116357" />
            <mass value="0.002203374250243251" />
            <inertia ixx="0.0" ixy="-0.0" ixz="-0.0" iyy="0.0" iyz="0.0" izz="0.0" />
        </inertial>
        <visual>
            <origin rpy="0 0 0" xyz="-0.046 0.0235 -0.0065" />
            <geometry>
                <mesh filename="package://gripkit_cr_plus_l_bb_description/meshes/ISO_4762_-_M4_x_12ISO_2.stl" scale="0.001 0.001 0.001" />
            </geometry>
            <material name="silver" />
        </visual>
        <collision>
            <origin rpy="0 0 0" xyz="-0.046 0.0235 -0.0065" />
            <geometry>
                <mesh filename="package://gripkit_cr_plus_l_bb_description/meshes/ISO_4762_-_M4_x_12ISO_2.stl" scale="0.001 0.001 0.001" />
            </geometry>
        </collision>
    </link>
    <link name="ISO_4762_-_M4_x_12ISO_3">
        <inertial>
            <origin rpy="0 0 0" xyz="6.938893903907228e-18 4.006101006481799e-13 0.0022480078452116357" />
            <mass value="0.002203374250243251" />
            <inertia ixx="0.0" ixy="0.0" ixz="-0.0" iyy="0.0" iyz="0.0" izz="0.0" />
        </inertial>
        <visual>
            <origin rpy="0 0 0" xyz="-0.046 -0.0235 -0.0065" />
            <geometry>
                <mesh filename="package://gripkit_cr_plus_l_bb_description/meshes/ISO_4762_-_M4_x_12ISO_3.stl" scale="0.001 0.001 0.001" />
            </geometry>
            <material name="silver" />
        </visual>
        <collision>
            <origin rpy="0 0 0" xyz="-0.046 -0.0235 -0.0065" />
            <geometry>
                <mesh filename="package://gripkit_cr_plus_l_bb_description/meshes/ISO_4762_-_M4_x_12ISO_3.stl" scale="0.001 0.001 0.001" />
            </geometry>
        </collision>
    </link>
    <link name="ISO_4762_-_M4_x_12ISO_4">
        <inertial>
            <origin rpy="0 0 0" xyz="-6.938893903907228e-18 4.006101006481799e-13 0.0022480078452116357" />
            <mass value="0.002203374250243251" />
            <inertia ixx="0.0" ixy="0.0" ixz="0.0" iyy="0.0" iyz="0.0" izz="0.0" />
        </inertial>
        <visual>
            <origin rpy="0 0 0" xyz="0.046 -0.0235 -0.0065" />
            <geometry>
                <mesh filename="package://gripkit_cr_plus_l_bb_description/meshes/ISO_4762_-_M4_x_12ISO_4.stl" scale="0.001 0.001 0.001" />
            </geometry>
            <material name="silver" />
        </visual>
        <collision>
            <origin rpy="0 0 0" xyz="0.046 -0.0235 -0.0065" />
            <geometry>
                <mesh filename="package://gripkit_cr_plus_l_bb_description/meshes/ISO_4762_-_M4_x_12ISO_4.stl" scale="0.001 0.001 0.001" />
            </geometry>
        </collision>
    </link>
    <link name="BE_20-030_CUSTOMER_v1_1">
        <inertial>
            <origin rpy="0 0 0" xyz="-0.01548587046158074 0.010207189127588168 0.00490301880176619" />
            <mass value="0.07101056528211638" />
            <inertia ixx="7e-06" ixy="4e-06" ixz="0.0" iyy="8e-06" iyz="-0.0" izz="1.4e-05" />
        </inertial>
        <visual>
            <origin rpy="0 0 0" xyz="0.002 0.0185 -0.081" />
            <geometry>
                <mesh filename="package://gripkit_cr_plus_l_bb_description/meshes/BE_20-030_CUSTOMER_v1_1.stl" scale="0.001 0.001 0.001" />
            </geometry>
            <material name="silver" />
        </visual>
        <collision>
            <origin rpy="0 0 0" xyz="0.002 0.0185 -0.081" />
            <geometry>
                <mesh filename="package://gripkit_cr_plus_l_bb_description/meshes/BE_20-030_CUSTOMER_v1_1.stl" scale="0.001 0.001 0.001" />
            </geometry>
        </collision>
    </link>
    <link name="BE_20-030_CUSTOMER_v1_2">
        <inertial>
            <origin rpy="0 0 0" xyz="0.015485870461580746 -0.010207189127588183 0.004903018801767051" />
            <mass value="0.07101056528211638" />
            <inertia ixx="7e-06" ixy="4e-06" ixz="-0.0" iyy="8e-06" iyz="0.0" izz="1.4e-05" />
        </inertial>
        <visual>
            <origin rpy="0 0 0" xyz="-0.002 -0.0185 -0.081" />
            <geometry>
                <mesh filename="package://gripkit_cr_plus_l_bb_description/meshes/BE_20-030_CUSTOMER_v1_2.stl" scale="0.001 0.001 0.001" />
            </geometry>
            <material name="silver" />
        </visual>
        <collision>
            <origin rpy="0 0 0" xyz="-0.002 -0.0185 -0.081" />
            <geometry>
                <mesh filename="package://gripkit_cr_plus_l_bb_description/meshes/BE_20-030_CUSTOMER_v1_2.stl" scale="0.001 0.001 0.001" />
            </geometry>
        </collision>
    </link>
    <link name="AC_20-025_CUSTOMER_v1_1">
        <inertial>
            <origin rpy="0 0 0" xyz="-0.001943760034278895 4.121102397658485e-17 0.014328388306272574" />
            <mass value="0.07018824497649055" />
            <inertia ixx="9e-06" ixy="-0.0" ixz="1e-06" iyy="9e-06" iyz="-0.0" izz="4e-06" />
        </inertial>
        <visual>
            <origin rpy="0 0 0" xyz="0.027 -0.0 -0.091" />
            <geometry>
                <mesh filename="package://gripkit_cr_plus_l_bb_description/meshes/AC_20-025_CUSTOMER_v1_1.stl" scale="0.001 0.001 0.001" />
            </geometry>
            <material name="silver" />
        </visual>
        <collision>
            <origin rpy="0 0 0" xyz="0.027 -0.0 -0.091" />
            <geometry>
                <mesh filename="package://gripkit_cr_plus_l_bb_description/meshes/AC_20-025_CUSTOMER_v1_1.stl" scale="0.001 0.001 0.001" />
            </geometry>
        </collision>
    </link>
    <link name="AC_20-025_CUSTOMER_v1_2">
        <inertial>
            <origin rpy="0 0 0" xyz="0.0019437600342788186 1.639628989286934e-17 0.014328388306273435" />
            <mass value="0.07018824497649055" />
            <inertia ixx="9e-06" ixy="-0.0" ixz="-1e-06" iyy="9e-06" iyz="0.0" izz="4e-06" />
        </inertial>
        <visual>
            <origin rpy="0 0 0" xyz="-0.027 0.0 -0.091" />
            <geometry>
                <mesh filename="package://gripkit_cr_plus_l_bb_description/meshes/AC_20-025_CUSTOMER_v1_2.stl" scale="0.001 0.001 0.001" />
            </geometry>
            <material name="silver" />
        </visual>
        <collision>
            <origin rpy="0 0 0" xyz="-0.027 0.0 -0.091" />
            <geometry>
                <mesh filename="package://gripkit_cr_plus_l_bb_description/meshes/AC_20-025_CUSTOMER_v1_2.stl" scale="0.001 0.001 0.001" />
            </geometry>
        </collision>
    </link>
    <link name="FT_20-CR_CUSTOMER_v1_1">
        <inertial>
            <origin rpy="0 0 0" xyz="0.0056745324669938944 -3.914404976963761e-15 0.020919520309735193" />
            <mass value="0.13587538757333883" />
            <inertia ixx="3e-05" ixy="-0.0" ixz="-5e-06" iyy="3.2e-05" iyz="-0.0" izz="1.1e-05" />
        </inertial>
        <visual>
            <origin rpy="0 0 0" xyz="0.027 -0.0 -0.116" />
            <geometry>
                <mesh filename="package://gripkit_cr_plus_l_bb_description/meshes/FT_20-CR_CUSTOMER_v1_1.stl" scale="0.001 0.001 0.001" />
            </geometry>
            <material name="silver" />
        </visual>
        <collision>
            <origin rpy="0 0 0" xyz="0.027 -0.0 -0.116" />
            <geometry>
                <mesh filename="package://gripkit_cr_plus_l_bb_description/meshes/FT_20-CR_CUSTOMER_v1_1.stl" scale="0.001 0.001 0.001" />
            </geometry>
        </collision>
    </link>
    <link name="FT_20-CR_CUSTOMER_v1_2">
        <inertial>
            <origin rpy="0 0 0" xyz="-0.005674532466994044 3.957899792938257e-15 0.020919520309735193" />
            <mass value="0.13587538757333883" />
            <inertia ixx="3e-05" ixy="-0.0" ixz="5e-06" iyy="3.2e-05" iyz="0.0" izz="1.1e-05" />
        </inertial>
        <visual>
            <origin rpy="0 0 0" xyz="-0.027 -0.0 -0.116" />
            <geometry>
                <mesh filename="package://gripkit_cr_plus_l_bb_description/meshes/FT_20-CR_CUSTOMER_v1_2.stl" scale="0.001 0.001 0.001" />
            </geometry>
            <material name="silver" />
        </visual>
        <collision>
            <origin rpy="0 0 0" xyz="-0.027 -0.0 -0.116" />
            <geometry>
                <mesh filename="package://gripkit_cr_plus_l_bb_description/meshes/FT_20-CR_CUSTOMER_v1_2.stl" scale="0.001 0.001 0.001" />
            </geometry>
        </collision>
    </link>
    <joint name="Rigid10" type="fixed">
        <origin rpy="0 0 0" xyz="0.046 -0.0235 0.011" />
        <parent link="SF-ISO50-CRG200_Customer" />
        <child link="CRG200_body" />
    </joint>
    <joint name="Slider01" type="prismatic">
        <origin rpy="0 0 0" xyz="-0.046 0.005 0.0576" />
        <parent link="CRG200_body" />
        <child link="CRG200_base_jaw_1" />
        <axis xyz="1.0 0.0 0.0" />
        <limit effort="100" lower="-0.021" upper="0.021" velocity="10" />
    </joint>
    <joint name="Slider02" type="prismatic">
        <origin rpy="0 0 0" xyz="-0.046 0.042 0.0576" />
        <parent link="CRG200_body" />
        <child link="CRG200_base_jaw_2" />
        <axis xyz="1.0 0.0 0.0" />
        <limit effort="100" lower="-0.021" upper="0.021" velocity="10" />
    </joint>
    <joint name="Rigid11" type="fixed">
        <origin rpy="0 0 0" xyz="-0.046 0.0235 0.0601" />
        <parent link="CRG200_body" />
        <child link="CRG200_top_cover" />
    </joint>
    <joint name="Rigid12" type="fixed">
        <origin rpy="0 0 0" xyz="-0.046 -0.0235 0.0065" />
        <parent link="SF-ISO50-CRG200_Customer" />
        <child link="ISO_4762_-_M4_x_12ISO_1" />
    </joint>
    <joint name="Rigid13" type="fixed">
        <origin rpy="0 0 0" xyz="0.046 -0.0235 0.0065" />
        <parent link="SF-ISO50-CRG200_Customer" />
        <child link="ISO_4762_-_M4_x_12ISO_2" />
    </joint>
    <joint name="Rigid14" type="fixed">
        <origin rpy="0 0 0" xyz="0.046 0.0235 0.0065" />
        <parent link="SF-ISO50-CRG200_Customer" />
        <child link="ISO_4762_-_M4_x_12ISO_3" />
    </joint>
    <joint name="Rigid15" type="fixed">
        <origin rpy="0 0 0" xyz="-0.046 0.0235 0.0065" />
        <parent link="SF-ISO50-CRG200_Customer" />
        <child link="ISO_4762_-_M4_x_12ISO_4" />
    </joint>
    <joint name="Rigid16" type="fixed">
        <origin rpy="0 0 0" xyz="-0.002 0.0 0.0124" />
        <parent link="CRG200_base_jaw_1" />
        <child link="BE_20-030_CUSTOMER_v1_1" />
    </joint>
    <joint name="Rigid17" type="fixed">
        <origin rpy="0 0 0" xyz="0.002 0.0 0.0124" />
        <parent link="CRG200_base_jaw_2" />
        <child link="BE_20-030_CUSTOMER_v1_2" />
    </joint>
    <joint name="Rigid18" type="fixed">
        <origin rpy="0 0 0" xyz="-0.025 0.0185 0.01" />
        <parent link="BE_20-030_CUSTOMER_v1_1" />
        <child link="AC_20-025_CUSTOMER_v1_1" />
    </joint>
    <joint name="Rigid19" type="fixed">
        <origin rpy="0 0 0" xyz="0.025 -0.0185 0.01" />
        <parent link="BE_20-030_CUSTOMER_v1_2" />
        <child link="AC_20-025_CUSTOMER_v1_2" />
    </joint>
    <joint name="Rigid20" type="fixed">
        <origin rpy="0 0 0" xyz="0.0 0.0 0.025" />
        <parent link="AC_20-025_CUSTOMER_v1_1" />
        <child link="FT_20-CR_CUSTOMER_v1_1" />
    </joint>
    <joint name="Rigid21" type="fixed">
        <origin rpy="0 0 0" xyz="0.0 0.0 0.025" />
        <parent link="AC_20-025_CUSTOMER_v1_2" />
        <child link="FT_20-CR_CUSTOMER_v1_2" />
    </joint>
    <joint name="Rigid09" type="fixed">
        <origin rpy="0 0 0" xyz="0 0 0.0351" />
        <parent link="kmriiwa_link_7" />
        <child link="SF-ISO50-CRG200_Customer" />
    </joint>
</robot>

